Workbook

Sheet Опросник
B2: Имя: | J2: Пол:
B4: Возраст:
B6: Образование:
B8: Дата:
B10: Инструкция:
B12: Ниже перечислены утверждения, с помощью которых Вы можете описать себя. Пожалуйста, прочитайте каждое утверждение и решите, насколько точно оно Вас характеризует. Если Вы не уверены, как ответить, основывайте свой ответ на том, как Вы ЧУВСТВУЕТЕ, а не на том, что Вы считаете правильным.
B14: Выберите подходящий вариант ответа и поставьте соответсвующий номер напротив утверждения.
B16: 1 = Абсолютно не соответствует | F16: 4 = В общем, соответствует
B17: 2 = По большей части не соответствует | F17: 5 = По большей части соотвествует
B18: 3 = Скорее соответствует, чем нет | F18: 6 = Полностью соответствует
B20: Утверждение: | Q20: Балл
B22: 1. Рядом со мной не было человека, который бы обо мне заботился, проявлял участие и искренний интерес ко всему, что происходило со мной | Q22: 4
B24: 2. Я «цепляюсь» за близких мне людей, так как боюсь, что они меня покинут | Q24: 4
B26: 3. Мне кажется, что другие люди меня используют | Q26: 4
B28: 4. Я не вписываюсь ни в одну из компаний | Q28: 4
B30: 5. Ни один человек, к которому я испытываю влечение, не мог бы полюбить меня, если бы узнал о моих недостатках | Q30: 2
B32: 6. Почти всё, что я делаю на работе (в учебе) не так хорошо, как это могли бы сделать другие люди | Q32: 1
B34: 7. Думаю, что я не способен самостоятельно справляться с повседневными делами | Q34: 2
B36: 8. Я не могу избавиться от ощущения, что должно случиться что-то плохое | Q36: 4
B38: 9. Я не смог «отделиться» от своих родителей в той мере, в какой это сделали мои сверстники | Q38: 2
B40: 10. Я думаю, что если я буду делать только то, что мне хочется, это непременно приведет к неприятностям | Q40: 2
B42: 11. В конце концов, именно мне приходится заботиться о моих близких | Q42: 3
B45: 1 = Абсолютно не соответствует | F45: 4 = В общем, соответствует
B46: 2 = По большей части не соответствует | F46: 5 = По большей части соотвествует
B47: 3 = Скорее соответствует, чем нет | F47: 6 = Полностью соответствует
B49: Утверждение: | Q49: Балл
B51: 12. Я слишком застенчив, чтобы проявлять свою симпатию (внимание или привязанность) к другим людям | Q51: 2
B53: 13. Я должен быть лучшим во всем, что я делаю, и не могу быть хуже других | Q53: 4
B55: 14. Мне очень трудно принять «нет» в качестве ответа, если я чего-нибудь хочу от других людей | Q55: 2
B57: 15. Я не могу заставить себя выполнять рутинные или скучные задания | Q57: 3
B59: 16. Знакомство с важными людьми и наличие денег дают мне ощущение собственной значимости | Q59: 2
B61: 17. Даже когда дела идут хорошо, у меня такое ощущение, что это ненадолго | Q61: 4
B63: 18. Если я допущу ошибку, то должен быть наказан | Q63: 2
B65: 19. Я не знаю таких людей, которые давали бы мне тепло, любовь и заботу | Q65: 1
B67: 20. Я так сильно нуждаюсь в других людях, что боюсь их потерять | Q67: 4
B69: 21. Я чувствую, что не могу ослабить свою защиту и вести себя естественно в присутствии других людей, так как они могут причинить мне боль | Q69: 3
B71: 22. Я очень сильно отличаюсь от других людей | Q71: 3
B74: 1 = Абсолютно не соответствует | F74: 4 = В общем, соответствует
B75: 2 = По большей части не соответствует | F75: 5 = По большей части соотвествует
B76: 3 = Скорее соответствует, чем нет | F76: 6 = Полностью соответствует
...

Sheet Результаты
B2: Имя: | C2: =Опросник!E2 | G2: Пол: | H2: =Опросник!M2
B4: Дата: | C4: =Опросник!E8
B6: № вопроса | C6: Балл | D6: Схема | E6: 5 | F6: 6 | G6: 5 или 6
B7: 1 | C7: =Опросник!Q22 | D7: ЭД | E7: =IF(C7=5,1,0) | F7: =IF(C7=6,1,0) | G7: =E7+F7
B8: 2 | C8: =Опросник!Q24 | D8: ПН | E8: =IF(C8=5,1,0) | F8: =IF(C8=6,1,0) | G8: =E8+F8
B9: 3 | C9: =Опросник!Q26 | D9: НН | E9: =IF(C9=5,1,0) | F9: =IF(C9=6,1,0) | G9: =E9+F9
B10: 4 | C10: =Опросник!Q28 | D10: СИО | E10: =IF(C10=5,1,0) | F10: =IF(C10=6,1,0) | G10: =E10+F10
B11: 5 | C11: =Опросник!Q30 | D11: ДС | E11: =IF(C11=5,1,0) | F11: =IF(C11=6,1,0) | G11: =E11+F11
B12: 6 | C12: =Опросник!Q32 | D12: НО | E12: =IF(C12=5,1,0) | F12: =IF(C12=6,1,0) | G12: =E12+F12
B13: 7 | C13: =Опросник!Q34 | D13: ЗН | E13: =IF(C13=5,1,0) | F13: =IF(C13=6,1,0) | G13: =E13+F13
B14: 8 | C14: =Опросник!Q36 | D14: У | E14: =IF(C14=5,1,0) | F14: =IF(C14=6,1,0) | G14: =E14+F14
B15: 9 | C15: =Опросник!Q38 | D15: СДНЯ | E15: =IF(C15=5,1,0) | F15: =IF(C15=6,1,0) | G15: =E15+F15
B16: 10 | C16: =Опросник!Q40 | D16: ПП | E16: =IF(C16=5,1,0) | F16: =IF(C16=6,1,0) | G16: =E16+F16
B17: 11 | C17: =Опросник!Q42 | D17: С | E17: =IF(C17=5,1,0) | F17: =IF(C17=6,1,0) | G17: =E17+F17
B18: 12 | C18: =Опросник!Q51 | D18: ПЭ | E18: =IF(C18=5,1,0) | F18: =IF(C18=6,1,0) | G18: =E18+F18
B19: 13 | C19: =Опросник!Q53 | D19: ЖС | E19: =IF(C19=5,1,0) | F19: =IF(C19=6,1,0) | G19: =E19+F19
B20: 14 | C20: =Опросник!Q55 | D20: ПГ | E20: =IF(C20=5,1,0) | F20: =IF(C20=6,1,0) | G20: =E20+F20
B21: 15 | C21: =Опросник!Q57 | D21: НС | E21: =IF(C21=5,1,0) | F21: =IF(C21=6,1,0) | G21: =E21+F21
B22: 16 | C22: =Опросник!Q59 | D22: ПО | E22: =IF(C22=5,1,0) | F22: =IF(C22=6,1,0) | G22: =E22+F22
B23: 17 | C23: =Опросник!Q61 | D23: НП | E23: =IF(C23=5,1,0) | F23: =IF(C23=6,1,0) | G23: =E23+F23
B24: 18 | C24: =Опросник!Q63 | D24: ПК | E24: =IF(C24=5,1,0) | F24: =IF(C24=6,1,0) | G24: =E24+F24
B25: 19 | C25: =Опросник!Q65 | D25: ЭД | E25: =IF(C25=5,1,0) | F25: =IF(C25=6,1,0) | G25: =E25+F25
B26: 20 | C26: =Опросник!Q67 | D26: ПН | E26: =IF(C26=5,1,0) | F26: =IF(C26=6,1,0) | G26: =E26+F26
B27: 21 | C27: =Опросник!Q69 | D27: НН | E27: =IF(C27=5,1,0) | F27: =IF(C27=6,1,0) | G27: =E27+F27
B28: 22 | C28: =Опросник!Q71 | D28: СИО | E28: =IF(C28=5,1,0) | F28: =IF(C28=6,1,0) | G28: =E28+F28
B29: 23 | C29: =Опросник!Q80 | D29: ДС | E29: =IF(C29=5,1,0) | F29: =IF(C29=6,1,0) | G29: =E29+F29
B30: 24 | C30: =Опросник!Q82 | D30: НО | E30: =IF(C30=5,1,0) | F30: =IF(C30=6,1,0) | G30: =E30+F30
B31: 25 | C31: =Опросник!Q84 | D31: ЗН | E31: =IF(C31=5,1,0) | F31: =IF(C31=6,1,0) | G31: =E31+F31
B32: 26 | C32: =Опросник!Q86 | D32: У | E32: =IF(C32=5,1,0) | F32: =IF(C32=6,1,0) | G32: =E32+F32
B33: 27 | C33: =Опросник!Q88 | D33: СДНЯ | E33: =IF(C33=5,1,0) | F33: =IF(C33=6,1,0) | G33: =E33+F33
B34: 28 | C34: =Опросник!Q90 | D34: ПП | E34: =IF(C34=5,1,0) | F34: =IF(C34=6,1,0) | G34: =E34+F34
B35: 29 | C35: =Опросник!Q92 | D35: С | E35: =IF(C35=5,1,0) | F35: =IF(C35=6,1,0) | G35: =E35+F35
B36: 30 | C36: =Опросник!Q94 | D36: ПЭ | E36: =IF(C36=5,1,0) | F36: =IF(C36=6,1,0) | G36: =E36+F36
B37: 31 | C37: =Опросник!Q96 | D37: ЖС | E37: =IF(C37=5,1,0) | F37: =IF(C37=6,1,0) | G37: =E37+F37
B38: 32 | C38: =Опросник!Q98 | D38: ПГ | E38: =IF(C38=5,1,0) | F38: =IF(C38=6,1,0) | G38: =E38+F38
B39: 33 | C39: =Опросник!Q100 | D39: НС | E39: =IF(C39=5,1,0) | F39: =IF(C39=6,1,0) | G39: =E39+F39
B40: 34 | C40: =Опросник!Q109 | D40: ПО | E40: =IF(C40=5,1,0) | F40: =IF(C40=6,1,0) | G40: =E40+F40
B41: 35 | C41: =Опросник!Q111 | D41: НП | E41: =IF(C41=5,1,0) | F41: =IF(C41=6,1,0) | G41: =E41+F41
B42: 36 | C42: =Опросник!Q113 | D42: ПК | E42: =IF(C42=5,1,0) | F42: =IF(C42=6,1,0) | G42: =E42+F42
B43: 37 | C43: =Опросник!Q115 | D43: ЭД | E43: =IF(C43=5,1,0) | F43: =IF(C43=6,1,0) | G43: =E43+F43
...
